<?xml version="1.0"?>

<robot name="mobileManipulator">

<material name="base-mat"><color rgba="0.5 0.5 0.5 1"/></material>
<material name="arm-joint-mat"><color rgba="0.73 0.33 1 1"/></material>
<material name="arm-link-mat"><color rgba="0.9 0.7 1 1"/></material>
<material name="arm-base-mat"><color rgba="0.73 0.33 1 1"/></material>
<material name="hand-material"><color rgba="1 0.5803922 0.8745098 1"/></material>

<link name="world"/>

<!-- ... Mobile Base ... -->

<link name="base_link_x">
  <inertial>
    <mass value="1.0"/>
    <origin rpy="0 0 0" xyz="0 0 0"/>
    <inertia ixx="1.0" ixy="0.0" ixz="0.0" iyy="1.0" iyz="0.0" izz="1.0"/>
  </inertial>
</link>

<link name="base_link_y">
  <inertial>
    <mass value="1.0"/>
    <origin rpy="0 0 0" xyz="0 0 0"/>
    <inertia ixx="1.0" ixy="0.0" ixz="0.0" iyy="1.0" iyz="0.0" izz="1.0"/>
  </inertial>
</link>

<link name="base_link">
  <inertial>
    <mass value="100.0"/>
    <origin rpy="0 0 0" xyz="0 0 0"/>
    <inertia ixx="1.0" ixy="0.0" ixz="0.0" iyy="1.0" iyz="0.0" izz="1.0"/>
  </inertial>
  <collision>
    <origin rpy="0.0 0 0" xyz="0 0 0"/>
    <geometry>
        <cylinder length="0.5" radius="0.2"/>
    </geometry>
  </collision>
  <visual>
    <origin rpy="0.0 0 0" xyz="0 0 0"/>
    <geometry>
        <cylinder length="0.5" radius="0.2"/>
    </geometry>
    <material name="base-mat"/>
  </visual>
</link>

<joint name="mobile_joint_x" type="prismatic">
  <safety_controller k_position="100.0" k_velocity="40.0" soft_lower_limit="-2.8973" soft_upper_limit="2.8973"/>
  <parent link="world"/>
  <child link="base_link_x"/>
  <origin rpy="0 0 0" xyz="0 0 0.25"/>
  <axis xyz="1 0 0"/>
  <limit effort="87" lower="-5" upper="5" velocity="2.1750"/>
</joint>

<joint name="mobile_joint_y" type="prismatic">
  <safety_controller k_position="100.0" k_velocity="40.0" soft_lower_limit="-2.8973" soft_upper_limit="2.8973"/>
  <parent link="base_link_x"/>
  <child link="base_link_y"/>
  <origin rpy="0 0 0" xyz="0 0 0"/>
  <axis xyz="0 1 0"/>
  <limit effort="87" lower="-5" upper="5" velocity="2.1750"/>
</joint>

<joint name="mobile_joint_theta" type="revolute">
  <parent link="base_link_y"/>
  <child link="base_link"/>
  <origin rpy="0 0 0" xyz="0 0 0"/>
  <axis xyz="0 0 1"/>
  <limit effort="87" lower="-5" upper="5" velocity="2.1750"/>
</joint>

<!-- ... Robot Arm ... -->

<joint name="shoulder-joint-fixed" type="fixed">
  <parent link="base_link"/>
  <child link="shoulder-link"/>
  <origin xyz="0 0 0.275"/>
  <limit effort="87" lower="-1" upper="1" velocity="-9.0"/>
</joint>

<link name="shoulder-link">
  <visual name="shoulder-link-vis">
      <origin xyz="0 0 0" rpy="0 1.5707964 0"/>
      <geometry><cylinder radius="0.025" length="0.1"/></geometry>
      <material name="arm-base-mat"/>
  </visual>
  <inertial>
    <mass value="0.0"/>
    <origin rpy="0 0 0" xyz="0 0 0"/>
    <inertia ixx="0.0" ixy="0.0" ixz="0.0" iyy="0.0" iyz="0.0" izz="0.0"/>
  </inertial>
</link>

<joint name="shoulder-joint" type="revolute">
  <parent link="shoulder-link"/>
  <child link="lower-arm-link"/>
  <origin xyz="0 0 0"/>
  <axis xyz="1 0 0"/>
  <limit effort="87" lower="-1.57079632679" upper="1.5707963267 " velocity="-9.0"/>
</joint>

<link name="lower-arm-link">
  <visual name="lower-arm-link-vis">
      <origin xyz="0 0 0.25"/>
      <geometry><cylinder radius="0.025" length="0.5"/></geometry>
      <material name="arm-link-mat"/>
  </visual>
  <collision name="lower-arm-link-col">
      <origin xyz="0 0 0.25"/>
      <geometry><cylinder radius="0.025" length="0.5"/></geometry>
  </collision>
  <inertial>
    <mass value="0.0"/>
    <origin rpy="0 0 0" xyz="0 0 0"/>
    <inertia ixx="0.0" ixy="0.0" ixz="0.0" iyy="0.0" iyz="0.0" izz="0.0"/>
  </inertial>
</link>

<joint name="elbow-joint-fixed" type="fixed">
  <parent link="lower-arm-link"/>
  <child link="elbow-link"/>
  <origin xyz="0 0 0.5"/>
  <axis xyz="0 1 0"/>
  <limit effort="87" lower="-1.57" upper="1.57" velocity="-9.0"/>
</joint>

<link name="elbow-link">
  <visual name="elbow-link-vis">
      <origin xyz="0 0 0" rpy="1.5707964 0 0"/>
      <geometry><cylinder radius="0.025" length="0.05"/></geometry>
      <material name="arm-joint-mat"/>
  </visual>
  <inertial>
    <mass value="0.0"/>
    <origin rpy="0 0 0" xyz="0 0 0"/>
    <inertia ixx="0.0" ixy="0.0" ixz="0.0" iyy="0.0" iyz="0.0" izz="0.0"/>
  </inertial>
</link>

<joint name="elbow-joint" type="revolute">
  <parent link="elbow-link"/>
  <child link="fore-arm-link"/>
  <origin xyz="0 0 0"/>
  <axis xyz="0 1 0"/>
  <limit effort="87" lower="-1.57" upper="1.57" velocity="-9.0"/>
</joint>

<link name="fore-arm-link">
  <visual name="fore-arm-link-vis">
      <origin xyz="0 0 0.125"/>
      <geometry><cylinder radius="0.025" length="0.25"/></geometry>
      <material name="arm-link-mat"/>
  </visual>
  <collision name="fore-arm-link-col">
      <origin xyz="0 0 0.125"/>
      <geometry><cylinder radius="0.025" length="0.25"/></geometry>
  </collision>
  <inertial>
    <mass value="0.0"/>
    <origin rpy="0 0 0" xyz="0 0 0"/>
    <inertia ixx="0.0" ixy="0.0" ixz="0.0" iyy="0.0" iyz="0.0" izz="0.0"/>
  </inertial>
</link>

<joint name="wrist-joint-fixed" type="fixed">
  <origin xyz="0 0 0.25"/>
  <parent link="fore-arm-link"/>
  <child link="wrist-pitch-link"/>
  <limit effort="87" lower="-1.57" upper="1.57" velocity="-9.0"/>
</joint>

<link name="wrist-pitch-link">
  <visual name="wrist-link-vis">
      <origin rpy="1.5707964 0 0"/>
      <geometry><cylinder radius="0.025" length="0.05"/></geometry>
      <material name="arm-joint-mat"/>
  </visual>
  <inertial>
    <mass value="0.0"/>
    <origin rpy="0 0 0" xyz="0 0 0"/>
    <inertia ixx="0.0" ixy="0.0" ixz="0.0" iyy="0.0" iyz="0.0" izz="0.0"/>
  </inertial>
</link>

<joint name="wrist-pitch-joint" type="revolute">
  <parent link="wrist-pitch-link"/>
  <child link="wrist-roll-link"/>
  <axis xyz="0 1 0"/>
  <limit effort="87" lower="-1.57" upper="1.57" velocity="-9.0"/>
</joint>

<link name="wrist-roll-link">
  <visual name="wrist-roll-vis">
      <origin xyz="0 0 0.0625"/>
      <geometry><cylinder radius="0.025" length="0.125"/></geometry>
      <material name="arm-link-mat"/>
  </visual>
  <collision name="wrist-roll-col">
      <origin xyz="0 0 0.0625"/>
      <geometry><cylinder radius="0.025" length="0.125"/></geometry>
  </collision>
  
  <inertial>
    <mass value="0.0"/>
    <origin rpy="0 0 0" xyz="0 0 0"/>
    <inertia ixx="0.0" ixy="0.0" ixz="0.0" iyy="0.0" iyz="0.0" izz="0.0"/>
  </inertial>
</link>

<joint name="wrist-roll-joint" type="continuous">
  <parent link="wrist-roll-link"/>
  <child link="hand-link"/>
  <axis xyz="0 0 1"/>
  <limit effort="87" lower="-3.14" upper="3.14" velocity="-9.0"/>
</joint>

<link name="hand-link">
  <visual name="hand-link-vis">
      <origin xyz="0 0 0.175"/>
      <geometry><box size="0.01 0.05 0.1"/></geometry>
      <material name="hand-material"/>
  </visual>
  <collision name="hand-link-col">
      <origin xyz="0 0 0.175"/>
      <geometry><box size="0.01 0.05 0.1"/></geometry>
  </collision>
  <inertial>
    <mass value="0.0"/>
    <origin rpy="0 0 0" xyz="0 0 0"/>
    <inertia ixx="0.0" ixy="0.0" ixz="0.0" iyy="0.0" iyz="0.0" izz="0.0"/>
  </inertial>
</link>

</robot>
